<?xml version="1.0"?>
<robot name="arm">
    <link name = "axis">
    <visual>
        <origin xyz="0 0 0" rpy="0 0 0" />
    </visual>
    </link>
    
    <link name="base_link">
    <visual>
        <origin xyz="0 0 0.25" rpy="0 0 0" />
        <geometry>
        <cylinder radius="0.2" length=".5" />
        </geometry>
        <material name="gray" />
    </visual>
    </link>

  <joint name="axis_to_base" type="fixed">
    <parent link="axis"/>
    <child link="base_link"/>
  </joint>

  <link name="link1">
    <visual>
        <origin xyz="0 0 0.25" rpy="0 0 0" />
        <geometry>
        <cylinder radius="0.1" length=".5" />
        </geometry>
        <material name="gray" />
    </visual>
  </link>

   <joint name="base_to_link1" type="revolute">
   <axis xyz="0 0 1"/>
   <origin xyz="0 0 0.5" rpy="0 0 0"/>
   <limit effort="10" velocity="1" lower="-3.14" upper="3.14"/>
    <parent link="base_link"/>
    <child link="link1"/>
  </joint>

  <link name="link2">
    <visual>
        <origin xyz="0 0 0.25" rpy="0 0 0" />
        <geometry>
        <cylinder radius="0.1" length=".5" />
        </geometry>
        <material name="gray" />
    </visual>
  </link>

   <joint name="link1_to_link2" type="revolute">
   <axis xyz="0 1 0"/>
   <origin xyz="0 0 0.5" rpy="0 0 0"/>
   <limit effort="10" velocity="1" lower="-1.57" upper="1.57"/>
    <parent link="link1"/>
    <child link="link2"/>
  </joint>


  <link name="link3">
    <visual>
        <geometry>
        <cylinder radius="0.1" length=".5" />
        </geometry>
        <origin xyz="0 0 0.25" rpy="0 0 0" />
        <material name="gray" />
    </visual>
  </link>

  <joint name="link2_to_link3" type="revolute">
    <axis xyz="0 1 0"/>
    <origin xyz="0 0 0.5" />
     <limit effort="10" velocity="1" lower="-1.57" upper="1.57"/>
    <parent link="link2"/>
    <child link="link3"/>
  </joint>

  <link name="link4">
    <visual>
        <geometry>
        <cylinder radius="0.1" length=".5" />
        </geometry>
        <origin xyz="0.25 0 0" rpy="0 1.57 0" />
        <material name="gray" />
    </visual>
  </link>

  <joint name="link3_to_link4" type="revolute">
    <axis xyz="1 0 0"/>
    <origin xyz="0 0 0.5" />
    <limit effort="10" velocity="1" lower="-3.14" upper="3.14"/>
    <parent link="link3"/>
    <child link="link4"/>
  </joint>


  <link name="link5">
    <visual>
        <geometry>
        <cylinder radius="0.1" length=".5" />
        </geometry>
        <origin xyz="-0.05 0 0.25" rpy="0 0 0" />
        <material name="gray" />
    </visual>
  </link>

  <joint name="link4_to_link5" type="revolute">
    <axis xyz = "0 0 1"/>
    <origin xyz="0.5 0 0" />
    <limit effort="10" velocity="1" lower="-1.57" upper="1.57"/>
    <parent link="link4"/>
    <child link="link5"/>
  </joint>


  <link name="l5_6_connector1">
    <visual>
        <geometry>
        <cylinder radius="0.1" length=".5" />
        </geometry>
        <origin xyz="0.25 0 0" rpy="0 1.57 0" />
        <material name="gray" />
    </visual>
  </link>

  <joint name="link5_to_connector1" type="fixed">
    <origin xyz="0 0 0.5"/>
    <parent link="link5"/>
    <child link="l5_6_connector1"/>
  </joint>

  
  <link name="l5_6_connector2">
    <visual>
        <geometry>
        <cylinder radius="0.1" length=".5" />
        </geometry>
        <origin xyz="0 0 -0.25" rpy="0 0 0" />
        <material name="gray" />
    </visual>
  </link>

  <joint name="connector1_to_connector2" type="fixed">
    <origin xyz="0.5 0 0"/>
    <parent link="l5_6_connector1"/>
    <child link="l5_6_connector2"/>
  </joint>

  <link name="link6">
    <visual>
        <geometry>
        <cylinder radius="0.1" length=".5" />
        </geometry>
        <origin xyz="0.25 0 0.05" rpy="0 1.57 0" />
        <material name="gray" />
    </visual>
  </link>

  <joint name="connector2_to_link6" type="revolute">
    <axis xyz = "0 1 0"/>
    <origin xyz="0 0 -0.5"/>
    <limit effort="10" velocity="1" lower="-1.57" upper="1.57"/>
    <parent link="l5_6_connector2"/>
    <child link="link6"/>
  </joint>
</robot>
